Workbook
Name HealthScore: Dashboard!$T$16
Name JobDescriptionText: 'Skills Gap Analysis'!$A$4
Name JobFitScore: 'Skills Gap Analysis'!$C$48
Name ScoreA: Dashboard!$T$12
Name ScoreB: Dashboard!$T$13
Name ScoreC: Dashboard!$T$14
Name ScoreD: Dashboard!$T$15
Name TotalAchievedWeight: 'Skills Gap Analysis'!$C$47
Name TotalPossibleWeight: 'Skills Gap Analysis'!$C$46

Sheet Cover
B9: Job Search Analytics System
B11: Personal Job Search Management System
B14: Maintained by: | C14: Daniel | E14: Versioning Legend
B15: Version: | C15: 2.0.1 | E15: Architecture (X.0.0) – Structural redesign or core workflow changes
B16: Theme: | C16: Quiet Productivity | E16: Feature (0.X.0) – New features, dashboards, or metrics added
B17: Last Updated: | C17: =TEXT(TODAY(),"MMMM DD, YYYY") -> March 01, 2026 | E17: Refinement (0.0.X) – Fixes, formula updates, layout or wording improvements
B22: Built on the principles of Quiet Productivity — Calm. Clear. Audit-Ready.

Sheet Log
A1: Job Application Log | JobLogTable
A2: Date Applied | B2: Employer | C2: Job Title | D2: Source / How Applied | E2: Job Posting Link | F2: Resume Version Used | G2: Status | H2: Follow-Up Date | I2: Follow-Up Notes | J2: Interview Date | K2: Outcome | L2: Notes | M2: Days to Interview
A3: 46063 | B3: Acme Corp | C3: Sr. Business Analyst | D3: LinkedIn | E3: https://linkedin.com/1 | F3: BI-Focused | G3: Interview Scheduled | H3: 46068 | I3: Sent follow-up email | J3: 46073 | L3: Strong BI match | M3: =IF(J3="","",J3-A3) -> 10
A4: 46065 | B4: Globex Inc | C4: Operations Manager | D4: Indeed | E4: https://indeed.com/2 | F4: Ops-Focused | G4: Applied | H4: 46070 | L4: Need to follow up | M4: =IF(J4="","",J4-A4)
A5: 46067 | B5: Initech LLC | C5: Data Analyst | D5: Referral | E5: https://initech.com/jobs | F5: Master | G5: In Review | H5: 46072 | I5: Referred by Jane | M5: =IF(J5="","",J5-A5)
A6: 46070 | B6: Umbrella Co | C6: Project Manager | D6: Company Site | E6: https://umbrella.com/jobs | F6: PM-Focused | G6: Rejected | H6: 46075 | K6: Rejected | L6: Position filled internally | M6: =IF(J6="","",J6-A6)
A7: 46073 | B7: Stark Industries | C7: Analytics Lead | D7: LinkedIn | E7: https://linkedin.com/5 | F7: Tailored Version | G7: Applied | H7: 46078 | L7: Tailored resume submitted | M7: =IF(J7="","",J7-A7)
M8: =IF(J8="","",J8-A8)
M9: =IF(J9="","",J9-A9)
M10: =IF(J10="","",J10-A10)
M11: =IF(J11="","",J11-A11)
M12: =IF(J12="","",J12-A12)
M13: =IF(J13="","",J13-A13)
M14: =IF(J14="","",J14-A14)
M15: =IF(J15="","",J15-A15)
M16: =IF(J16="","",J16-A16)
M17: =IF(J17="","",J17-A17)
M18: =IF(J18="","",J18-A18)
M19: =IF(J19="","",J19-A19)
... M500: =IF(J500="","",J500-A500)

Sheet Dashboard
B2: Job Search Analytics Dashboard
B4: KEY PERFORMANCE INDICATORS
B6: =COUNTIFS(Log!A:A,">="&TODAY()-7) -> 0 | F6: =COUNTIFS(Log!H:H,"<"&TODAY(),Log!G:G,"Applied") -> 2 | J6: =IFERROR(COUNTIF(Log!G:G,"Interview Scheduled")/(COUNTA(Log!A:A)-1),0) -> 0.16666667 | N6: =IFERROR(COUNTIF(Log!G:G,"Offer")/(COUNTA(Log!A:A)-1),0) -> 0
B7: Applications This Week | F7: Follow-Ups Due | J7: Interview Rate | N7: Offer Rate
B10: JOB SEARCH HEALTH SCORE (0 – 100)
B11: Application Activity (0–30): | K11: =T12 -> 0 | N11: 30%
B12: Follow-Up Discipline (0–30): | K12: =T13 -> 10 | N12: 30% | T12: =MIN((COUNTIFS(Log!A:A,">="&TODAY()-7)/5)*30,30) -> 0
B13: Interview Rate Score (0–25): | K13: =T14 -> 4.1666667 | N13: 25% | T13: =MAX(30-(COUNTIFS(Log!H:H,"<"&TODAY(),Log!G:G,"Applied")*10),0) -> 10
B14: Offer Rate Score (0–15): | K14: =T15 -> 0 | N14: 15% | T14: =IFERROR(MIN((COUNTIF(Log!G:G,"Interview Scheduled")/(COUNTA(Log!A:A)-1))*25,25),0) -> 4.1666667
B15: TOTAL HEALTH SCORE (0–100): | K15: =T16 -> 14.166667 | T15: =IFERROR(MIN((COUNTIF(Log!G:G,"Offer")/(COUNTA(Log!A:A)-1))*15,15),0) -> 0
T16: =T12+T13+T14+T15 -> 14.166667
B17: RÉSUMÉ PERFORMANCE ANALYSIS
B18: Résumé Version | C18: Applications | D18: Interviews | E18: Offers | F18: Interview Rate | G18: Offer Rate
B19: Master | C19: =COUNTIF(Log!F:F,"Master") -> 1 | D19: =COUNTIFS(Log!F:F,"Master",Log!G:G,"Interview Scheduled") -> 0 | E19: =COUNTIFS(Log!F:F,"Master",Log!G:G,"Offer") -> 0 | F19: =IFERROR(D19/C19,0) -> 0 | G19: =IFERROR(E19/C19,0) -> 0
B20: BI-Focused | C20: =COUNTIF(Log!F:F,"BI-Focused") -> 1 | D20: =COUNTIFS(Log!F:F,"BI-Focused",Log!G:G,"Interview Scheduled") -> 1 | E20: =COUNTIFS(Log!F:F,"BI-Focused",Log!G:G,"Offer") -> 0 | F20: =IFERROR(D20/C20,0) -> 1 | G20: =IFERROR(E20/C20,0) -> 0
B21: PM-Focused | C21: =COUNTIF(Log!F:F,"PM-Focused") -> 1 | D21: =COUNTIFS(Log!F:F,"PM-Focused",Log!G:G,"Interview Scheduled") -> 0 | E21: =COUNTIFS(Log!F:F,"PM-Focused",Log!G:G,"Offer") -> 0 | F21: =IFERROR(D21/C21,0) -> 0 | G21: =IFERROR(E21/C21,0) -> 0
B22: Ops-Focused | C22: =COUNTIF(Log!F:F,"Ops-Focused") -> 1 | D22: =COUNTIFS(Log!F:F,"Ops-Focused",Log!G:G,"Interview Scheduled") -> 0 | E22: =COUNTIFS(Log!F:F,"Ops-Focused",Log!G:G,"Offer") -> 0 | F22: =IFERROR(D22/C22,0) -> 0 | G22: =IFERROR(E22/C22,0) -> 0
B23: Tailored Version | C23: =COUNTIF(Log!F:F,"Tailored Version") -> 1 | D23: =COUNTIFS(Log!F:F,"Tailored Version",Log!G:G,"Interview Scheduled") -> 0 | E23: =COUNTIFS(Log!F:F,"Tailored Version",Log!G:G,"Offer") -> 0 | F23: =IFERROR(D23/C23,0) -> 0 | G23: =IFERROR(E23/C23,0) -> 0
B26: APPLICATION STATUS BREAKDOWN
B27: Status | C27: Count | D27: % of Total
B28: Applied | C28: =COUNTIF(Log!G:G,"Applied") -> 2 | D28: =IFERROR(C28/(COUNTA(Log!A:A)-2),0) -> 0.4
B29: In Review | C29: =COUNTIF(Log!G:G,"In Review") -> 1 | D29: =IFERROR(C29/(COUNTA(Log!A:A)-2),0) -> 0.2
B30: Interview Scheduled | C30: =COUNTIF(Log!G:G,"Interview Scheduled") -> 1 | D30: =IFERROR(C30/(COUNTA(Log!A:A)-2),0) -> 0.2
B31: Interviewed | C31: =COUNTIF(Log!G:G,"Interviewed") -> 0 | D31: =IFERROR(C31/(COUNTA(Log!A:A)-2),0) -> 0
B32: Offer | C32: =COUNTIF(Log!G:G,"Offer") -> 0 | D32: =IFERROR(C32/(COUNTA(Log!A:A)-2),0) -> 0
B33: Rejected | C33: =COUNTIF(Log!G:G,"Rejected") -> 1 | D33: =IFERROR(C33/(COUNTA(Log!A:A)-2),0) -> 0.2
B34: Closed / No Response | C34: =COUNTIF(Log!G:G,"Closed / No Response") -> 0 | D34: =IFERROR(C34/(COUNTA(Log!A:A)-2),0) -> 0
B35: TOTAL | C35: =COUNTA(Log!A:A)-2 -> 5 | D35: 100.0%
K37: MACRO BUTTONS (Assign macros to shape buttons)
K38: [ Refresh Dashboard ] | O38: → RefreshDashboard
K39: [ Weekly Summary ] | O39: → WeeklySummary
K40: [ Update Pivot Tables ] | O40: → UpdatePivotSources

Sheet Analytics
A1: Analytics — Pivot Table Engine & Summary Tables
A2: INSERT EXCEL PIVOT TABLES from JobLogTable in each section. Pivot names: ptApplicationsByWeek | ptStatusBreakdown | ptResumePerformance | ptTimeToInterview
A4: PIVOT 1 — Applications by Week (ptApplicationsByWeek)
A5: Week Of | B5: Applications
A6: ← Insert ptApplicationsByWeek here
A9: PIVOT 2 — Status Breakdown (ptStatusBreakdown)
A10: Status | B10: Count
A11: Applied | B11: =COUNTIF(Log!G:G,"Applied") -> 2
A12: In Review | B12: =COUNTIF(Log!G:G,"In Review") -> 1
A13: Interview Scheduled | B13: =COUNTIF(Log!G:G,"Interview Scheduled") -> 1
A14: Interviewed | B14: =COUNTIF(Log!G:G,"Interviewed") -> 0
A15: Offer | B15: =COUNTIF(Log!G:G,"Offer") -> 0
A16: Rejected | B16: =COUNTIF(Log!G:G,"Rejected") -> 1
A17: Closed / No Response | B17: =COUNTIF(Log!G:G,"Closed / No Response") -> 0
A20: PIVOT 3 — Résumé Performance (ptResumePerformance)
A21: Résumé Version | B21: Applications | C21: Interviews | D21: Offers | E21: Int. Rate | F21: Offer Rate
A22: Master | B22: =COUNTIF(Log!F:F,"Master") -> 1 | C22: =COUNTIFS(Log!F:F,"Master",Log!G:G,"Interview Scheduled") -> 0 | D22: =COUNTIFS(Log!F:F,"Master",Log!G:G,"Offer") -> 0 | E22: =IFERROR(C22/B22,0) -> 0 | F22: =IFERROR(D22/B22,0) -> 0
A23: BI-Focused | B23: =COUNTIF(Log!F:F,"BI-Focused") -> 1 | C23: =COUNTIFS(Log!F:F,"BI-Focused",Log!G:G,"Interview Scheduled") -> 1 | D23: =COUNTIFS(Log!F:F,"BI-Focused",Log!G:G,"Offer") -> 0 | E23: =IFERROR(C23/B23,0) -> 1 | F23: =IFERROR(D23/B23,0) -> 0
A24: PM-Focused | B24: =COUNTIF(Log!F:F,"PM-Focused") -> 1 | C24: =COUNTIFS(Log!F:F,"PM-Focused",Log!G:G,"Interview Scheduled") -> 0 | D24: =COUNTIFS(Log!F:F,"PM-Focused",Log!G:G,"Offer") -> 0 | E24: =IFERROR(C24/B24,0) -> 0 | F24: =IFERROR(D24/B24,0) -> 0
A25: Ops-Focused | B25: =COUNTIF(Log!F:F,"Ops-Focused") -> 1 | C25: =COUNTIFS(Log!F:F,"Ops-Focused",Log!G:G,"Interview Scheduled") -> 0 | D25: =COUNTIFS(Log!F:F,"Ops-Focused",Log!G:G,"Offer") -> 0 | E25: =IFERROR(C25/B25,0) -> 0 | F25: =IFERROR(D25/B25,0) -> 0
A26: Tailored Version | B26: =COUNTIF(Log!F:F,"Tailored Version") -> 1 | C26: =COUNTIFS(Log!F:F,"Tailored Version",Log!G:G,"Interview Scheduled") -> 0 | D26: =COUNTIFS(Log!F:F,"Tailored Version",Log!G:G,"Offer") -> 0 | E26: =IFERROR(C26/B26,0) -> 0 | F26: =IFERROR(D26/B26,0) -> 0
A30: PIVOT 4 — Time-to-Interview (ptTimeToInterview)
A31: Days to Interview | B31: Count
A32: ← Insert ptTimeToInterview pivot here
A35: WEEKLY ACTIVITY — Last 8 Weeks (feeds Weekly Activity Chart)
A36: Week Start | B36: Week End | C36: Applications | D36: Interviews | E36: Offers
A37: =TODAY()-56 -> 46026 | B37: =A37+6 -> 46032 | C37: =COUNTIFS(Log!A:A,">="&A37,Log!A:A,"<="&B37) -> 0 | D37: =COUNTIFS(Log!A:A,">="&A37,Log!A:A,"<="&B37,Log!G:G,"Interview Scheduled") -> 0 | E37: =COUNTIFS(Log!A:A,">="&A37,Log!A:A,"<="&B37,Log!G:G,"Offer") -> 0
A38: =TODAY()-49 -> 46033 | B38: =A38+6 -> 46039 | C38: =COUNTIFS(Log!A:A,">="&A38,Log!A:A,"<="&B38) -> 0 | D38: =COUNTIFS(Log!A:A,">="&A38,Log!A:A,"<="&B38,Log!G:G,"Interview Scheduled") -> 0 | E38: =COUNTIFS(Log!A:A,">="&A38,Log!A:A,"<="&B38,Log!G:G,"Offer") -> 0
A39: =TODAY()-42 -> 46040 | B39: =A39+6 -> 46046 | C39: =COUNTIFS(Log!A:A,">="&A39,Log!A:A,"<="&B39) -> 0 | D39: =COUNTIFS(Log!A:A,">="&A39,Log!A:A,"<="&B39,Log!G:G,"Interview Scheduled") -> 0 | E39: =COUNTIFS(Log!A:A,">="&A39,Log!A:A,"<="&B39,Log!G:G,"Offer") -> 0
A40: =TODAY()-35 -> 46047 | B40: =A40+6 -> 46053 | C40: =COUNTIFS(Log!A:A,">="&A40,Log!A:A,"<="&B40) -> 0 | D40: =COUNTIFS(Log!A:A,">="&A40,Log!A:A,"<="&B40,Log!G:G,"Interview Scheduled") -> 0 | E40: =COUNTIFS(Log!A:A,">="&A40,Log!A:A,"<="&B40,Log!G:G,"Offer") -> 0
A41: =TODAY()-28 -> 46054 | B41: =A41+6 -> 46060 | C41: =COUNTIFS(Log!A:A,">="&A41,Log!A:A,"<="&B41) -> 0 | D41: =COUNTIFS(Log!A:A,">="&A41,Log!A:A,"<="&B41,Log!G:G,"Interview Scheduled") -> 0 | E41: =COUNTIFS(Log!A:A,">="&A41,Log!A:A,"<="&B41,Log!G:G,"Offer") -> 0
A42: =TODAY()-21 -> 46061 | B42: =A42+6 -> 46067 | C42: =COUNTIFS(Log!A:A,">="&A42,Log!A:A,"<="&B42) -> 3 | D42: =COUNTIFS(Log!A:A,">="&A42,Log!A:A,"<="&B42,Log!G:G,"Interview Scheduled") -> 1 | E42: =COUNTIFS(Log!A:A,">="&A42,Log!A:A,"<="&B42,Log!G:G,"Offer") -> 0
A43: =TODAY()-14 -> 46068 | B43: =A43+6 -> 46074 | C43: =COUNTIFS(Log!A:A,">="&A43,Log!A:A,"<="&B43) -> 2 | D43: =COUNTIFS(Log!A:A,">="&A43,Log!A:A,"<="&B43,Log!G:G,"Interview Scheduled") -> 0 | E43: =COUNTIFS(Log!A:A,">="&A43,Log!A:A,"<="&B43,Log!G:G,"Offer") -> 0
A44: =TODAY()-7 -> 46075 | B44: =A44+6 -> 46081 | C44: =COUNTIFS(Log!A:A,">="&A44,Log!A:A,"<="&B44) -> 0 | D44: =COUNTIFS(Log!A:A,">="&A44,Log!A:A,"<="&B44,Log!G:G,"Interview Scheduled") -> 0 | E44: =COUNTIFS(Log!A:A,">="&A44,Log!A:A,"<="&B44,Log!G:G,"Offer") -> 0

Sheet Timeline
A1: Job Search Timeline — Scatter Chart Helper
A2: Helper table → Scatter Chart (Markers Only). X=Date col, Y=Y-Value (=1). Label each point with Event col text, positioned Above. Chart BG: #1E1E1E | Gridlines: #C9D1D3 | Hide Y-axis | Hide legend.
A3: Date | B3: Event | C3: Event Type | D3: Y-Value
A4: =IF(Log!A3="","",Log!A3) -> 46063 | B4: ="Applied: "&Log!C3&" at "&Log!B3 -> Applied: Sr. Business Analyst at Acme Corp | C4: Applied | D4: 1
A5: =IF(Log!H3="","",Log!H3) -> 46068 | B5: ="Follow-Up: "&Log!C3&" at "&Log!B3 -> Follow-Up: Sr. Business Analyst at Acme Corp | C5: Follow-Up | D5: 1
A6: =IF(Log!J3="","",Log!J3) -> 46073 | B6: ="Interview: "&Log!C3&" at "&Log!B3 -> Interview: Sr. Business Analyst at Acme Corp | C6: Interview | D6: 1
A7: =IF(Log!K3<>"",Log!J3,"") | B7: =IF(Log!K3<>"","Outcome: "&Log!C3&" at "&Log!B3,"") | C7: Outcome | D7: 1
A8: =IF(Log!A4="","",Log!A4) -> 46065 | B8: ="Applied: "&Log!C4&" at "&Log!B4 -> Applied: Operations Manager at Globex Inc | C8: Applied | D8: 1
A9: =IF(Log!H4="","",Log!H4) -> 46070 | B9: ="Follow-Up: "&Log!C4&" at "&Log!B4 -> Follow-Up: Operations Manager at Globex Inc | C9: Follow-Up | D9: 1
A10: =IF(Log!J4="","",Log!J4) | B10: ="Interview: "&Log!C4&" at "&Log!B4 -> Interview: Operations Manager at Globex Inc | C10: Interview | D10: 1
A11: =IF(Log!K4<>"",Log!J4,"") | B11: =IF(Log!K4<>"","Outcome: "&Log!C4&" at "&Log!B4,"") | C11: Outcome | D11: 1
A12: =IF(Log!A5="","",Log!A5) -> 46067 | B12: ="Applied: "&Log!C5&" at "&Log!B5 -> Applied: Data Analyst at Initech LLC | C12: Applied | D12: 1
A13: =IF(Log!H5="","",Log!H5) -> 46072 | B13: ="Follow-Up: "&Log!C5&" at "&Log!B5 -> Follow-Up: Data Analyst at Initech LLC | C13: Follow-Up | D13: 1
A14: =IF(Log!J5="","",Log!J5) | B14: ="Interview: "&Log!C5&" at "&Log!B5 -> Interview: Data Analyst at Initech LLC | C14: Interview | D14: 1
A15: =IF(Log!K5<>"",Log!J5,"") | B15: =IF(Log!K5<>"","Outcome: "&Log!C5&" at "&Log!B5,"") | C15: Outcome | D15: 1
A16: =IF(Log!A6="","",Log!A6) -> 46070 | B16: ="Applied: "&Log!C6&" at "&Log!B6 -> Applied: Project Manager at Umbrella Co | C16: Applied | D16: 1
A17: =IF(Log!H6="","",Log!H6) -> 46075 | B17: ="Follow-Up: "&Log!C6&" at "&Log!B6 -> Follow-Up: Project Manager at Umbrella Co | C17: Follow-Up | D17: 1
A18: =IF(Log!J6="","",Log!J6) | B18: ="Interview: "&Log!C6&" at "&Log!B6 -> Interview: Project Manager at Umbrella Co | C18: Interview | D18: 1
A19: =IF(Log!K6<>"",Log!J6,"") -> 0 | B19: =IF(Log!K6<>"","Outcome: "&Log!C6&" at "&Log!B6,"") -> Outcome: Project Manager at Umbrella Co | C19: Outcome | D19: 1
A20: =IF(Log!A7="","",Log!A7) -> 46073 | B20: ="Applied: "&Log!C7&" at "&Log!B7 -> Applied: Analytics Lead at Stark Industries | C20: Applied | D20: 1
A21: =IF(Log!H7="","",Log!H7) -> 46078 | B21: ="Follow-Up: "&Log!C7&" at "&Log!B7 -> Follow-Up: Analytics Lead at Stark Industries | C21: Follow-Up | D21: 1
A22: =IF(Log!J7="","",Log!J7) | B22: ="Interview: "&Log!C7&" at "&Log!B7 -> Interview: Analytics Lead at Stark Industries | C22: Interview | D22: 1
A23: =IF(Log!K7<>"",Log!J7,"") | B23: =IF(Log!K7<>"","Outcome: "&Log!C7&" at "&Log!B7,"") | C23: Outcome | D23: 1
A24: Color guide: Applied=#4F8A8B | Follow-Up=#E8C07D | Interview=#7FB77E | Outcome=#C97A7A

Sheet Skills Gap Analysis
A1: Skills Gap Analysis Engine
A3: JOB DESCRIPTION INPUT — Paste job posting text here (used by ExtractSkills macro)
A4: [PASTE JOB DESCRIPTION TEXT HERE]
A6: SKILLS DICTIONARY (SkillsDictionary) | E6: RESUME SKILLS (ResumeSkills) | H6: JOB POSTING SKILLS (JobPostingSkills — auto-populated by ExtractSkills)
A7: Skill | B7: Category | C7: Weight | E7: Skill | F7: Category | H7: Skill | I7: Category | J7: Weight
A8: Power BI | B8: Tools | C8: 5 | E8: Power BI | F8: Tools | H8: Power BI | I8: Tools | J8: 5
A9: DAX | B9: Technical | C9: 5 | E9: DAX | F9: Technical | H9: DAX | I9: Technical | J9: 5
A10: SQL | B10: Technical | C10: 5 | E10: SQL | F10: Technical | H10: SQL | I10: Technical | J10: 4
A11: Data Analysis | B11: Technical | C11: 4 | E11: Excel | F11: Tools | H11: Python | I11: Technical | J11: 4
A12: Excel | B12: Tools | C12: 4 | E12: Data Analysis | F12: Technical | H12: Data Analysis | I12: Technical | J12: 5
A13: Python | B13: Technical | C13: 4 | E13: Business Analysis | F13: Domain | H13: Business Analysis | I13: Domain | J13: 5
A14: Tableau | B14: Tools | C14: 3 | E14: KPI Reporting | F14: Technical | H14: Azure / Cloud | I14: Technical | J14: 3
A15: Project Management | B15: Domain | C15: 4 | E15: Project Management | F15: Domain | H15: Project Management | I15: Domain | J15: 3
A16: Stakeholder Mgmt | B16: Soft | C16: 3 | E16: Stakeholder Mgmt | F16: Soft | H16: Communication | I16: Soft | J16: 3
A17: Process Improvement | B17: Domain | C17: 4 | E17: Process Improvement | F17: Domain | H17: Agile / Scrum | I17: Domain | J17: 2
A18: Communication | B18: Soft | C18: 3 | E18: Communication | F18: Soft | H18: ETL Pipelines | I18: Technical | J18: 3
A19: Agile / Scrum | B19: Domain | C19: 3 | E19: Cross-functional | F19: Soft | H19: KPI Reporting | I19: Technical | J19: 4
A20: Business Analysis | B20: Domain | C20: 5 | E20: Agile / Scrum | F20: Domain
A21: KPI Reporting | B21: Technical | C21: 4 | E21: Strategic Planning | F21: Domain
A22: ETL Pipelines | B22: Technical | C22: 3 | E22: Presentation Skills | F22: Soft
A23: Azure / Cloud | B23: Technical | C23: 3
A24: R | B24: Technical | C24: 2
A25: Presentation Skills | B25: Soft | C25: 3
A26: Cross-functional | B26: Soft | C26: 4
A27: Strategic Planning | B27: Domain | C27: 3
A30: SKILLS GAP SCORING TABLE (SkillsGap) — Weighted Model
A31: Skill | B31: Category | C31: Weight | D31: Is In Resume | E31: Weighted Score | F31: Weighted Gap | G31: Gap Rank | H31: Strength Rank
A32: Power BI | B32: Tools | C32: 5 | D32: =IF(COUNTIF(ResumeSkills[Skill],A32)>0,1,0) -> 1 | E32: =C32*D32 -> 5 | F32: =IF(D32=1,0,C32) -> 0 | G32: =IFERROR(RANK(F32,$F$32:$F$43,0),"") -> 4 | H32: =IFERROR(RANK(E32,$E$32:$E$43,0),"") -> 1
A33: DAX | B33: Technical | C33: 5 | D33: =IF(COUNTIF(ResumeSkills[Skill],A33)>0,1,0) -> 1 | E33: =C33*D33 -> 5 | F33: =IF(D33=1,0,C33) -> 0 | G33: =IFERROR(RANK(F33,$F$32:$F$43,0),"") -> 4 | H33: =IFERROR(RANK(E33,$E$32:$E$43,0),"") -> 1
A34: SQL | B34: Technical | C34: 4 | D34: =IF(COUNTIF(ResumeSkills[Skill],A34)>0,1,0) -> 1 | E34: =C34*D34 -> 4 | F34: =IF(D34=1,0,C34) -> 0 | G34: =IFERROR(RANK(F34,$F$32:$F$43,0),"") -> 4 | H34: =IFERROR(RANK(E34,$E$32:$E$43,0),"") -> 5
A35: Python | B35: Technical | C35: 4 | D35: =IF(COUNTIF(ResumeSkills[Skill],A35)>0,1,0) -> 0 | E35: =C35*D35 -> 0 | F35: =IF(D35=1,0,C35) -> 4 | G35: =IFERROR(RANK(F35,$F$32:$F$43,0),"") -> 1 | H35: =IFERROR(RANK(E35,$E$32:$E$43,0),"") -> 10
A36: Data Analysis | B36: Technical | C36: 5 | D36: =IF(COUNTIF(ResumeSkills[Skill],A36)>0,1,0) -> 1 | E36: =C36*D36 -> 5 | F36: =IF(D36=1,0,C36) -> 0 | G36: =IFERROR(RANK(F36,$F$32:$F$43,0),"") -> 4 | H36: =IFERROR(RANK(E36,$E$32:$E$43,0),"") -> 1
A37: Business Analysis | B37: Domain | C37: 5 | D37: =IF(COUNTIF(ResumeSkills[Skill],A37)>0,1,0) -> 1 | E37: =C37*D37 -> 5 | F37: =IF(D37=1,0,C37) -> 0 | G37: =IFERROR(RANK(F37,$F$32:$F$43,0),"") -> 4 | H37: =IFERROR(RANK(E37,$E$32:$E$43,0),"") -> 1
A38: Azure / Cloud | B38: Technical | C38: 3 | D38: =IF(COUNTIF(ResumeSkills[Skill],A38)>0,1,0) -> 0 | E38: =C38*D38 -> 0 | F38: =IF(D38=1,0,C38) -> 3 | G38: =IFERROR(RANK(F38,$F$32:$F$43,0),"") -> 2 | H38: =IFERROR(RANK(E38,$E$32:$E$43,0),"") -> 10
A39: Project Management | B39: Domain | C39: 3 | D39: =IF(COUNTIF(ResumeSkills[Skill],A39)>0,1,0) -> 1 | E39: =C39*D39 -> 3 | F39: =IF(D39=1,0,C39) -> 0 | G39: =IFERROR(RANK(F39,$F$32:$F$43,0),"") -> 4 | H39: =IFERROR(RANK(E39,$E$32:$E$43,0),"") -> 7
A40: Communication | B40: Soft | C40: 3 | D40: =IF(COUNTIF(ResumeSkills[Skill],A40)>0,1,0) -> 1 | E40: =C40*D40 -> 3 | F40: =IF(D40=1,0,C40) -> 0 | G40: =IFERROR(RANK(F40,$F$32:$F$43,0),"") -> 4 | H40: =IFERROR(RANK(E40,$E$32:$E$43,0),"") -> 7
A41: Agile / Scrum | B41: Domain | C41: 2 | D41: =IF(COUNTIF(ResumeSkills[Skill],A41)>0,1,0) -> 1 | E41: =C41*D41 -> 2 | F41: =IF(D41=1,0,C41) -> 0 | G41: =IFERROR(RANK(F41,$F$32:$F$43,0),"") -> 4 | H41: =IFERROR(RANK(E41,$E$32:$E$43,0),"") -> 9
A42: ETL Pipelines | B42: Technical | C42: 3 | D42: =IF(COUNTIF(ResumeSkills[Skill],A42)>0,1,0) -> 0 | E42: =C42*D42 -> 0 | F42: =IF(D42=1,0,C42) -> 3 | G42: =IFERROR(RANK(F42,$F$32:$F$43,0),"") -> 2 | H42: =IFERROR(RANK(E42,$E$32:$E$43,0),"") -> 10
A43: KPI Reporting | B43: Technical | C43: 4 | D43: =IF(COUNTIF(ResumeSkills[Skill],A43)>0,1,0) -> 1 | E43: =C43*D43 -> 4 | F43: =IF(D43=1,0,C43) -> 0 | G43: =IFERROR(RANK(F43,$F$32:$F$43,0),"") -> 4 | H43: =IFERROR(RANK(E43,$E$32:$E$43,0),"") -> 5
A45: JOB FIT SCORE
...

Sheet Documentation
A1: System Documentation & Reference Guide
A2: SYSTEM OVERVIEW
A3: Purpose: | B3: Structured, data-driven, audit-ready job search management in Excel
A4: Version: | B4: 2026.1
A5: Maintained by: | B5: Daniel
A6: Design Theme: | B6: Quiet Productivity — Calm, low-noise, high-clarity
A8: SHEET DESCRIPTIONS
A9: Cover | B9: Professional front page + version metadata
A10: Log | B10: JobLogTable — 13 columns — primary data entry sheet
A11: Dashboard | B11: KPIs + Health Score + Résumé Performance + Status Breakdown + Charts
A12: Analytics | B12: Pivot engine: ptApplicationsByWeek | ptStatusBreakdown | ptResumePerformance | ptTimeToInterview
A13: Timeline | B13: Scatter chart visualizing all events chronologically
A14: Skills Gap Analysis | B14: Skills Dictionary + Resume Skills + Job Posting Skills + Gap Scoring + Job Fit Score
A15: Documentation | B15: This sheet — all formulas, named ranges, macros, conditional formatting
A17: NAMED RANGES
A18: ScoreA | B18: Dashboard!$T$12 — Application Activity Score (0–30)
A19: ScoreB | B19: Dashboard!$T$13 — Follow-Up Discipline Score (0–30)
A20: ScoreC | B20: Dashboard!$T$14 — Interview Rate Score (0–25)
A21: ScoreD | B21: Dashboard!$T$15 — Offer Rate Score (0–15)
A22: HealthScore | B22: Dashboard!$T$16 — Final Health Score = ScoreA+ScoreB+ScoreC+ScoreD
A23: TotalPossibleWeight | B23: Skills Gap Analysis — =SUM(JobPostingSkills[Weight])
A24: TotalAchievedWeight | B24: Skills Gap Analysis — =SUM(SkillsGap[Weighted Score])
A25: JobFitScore | B25: Skills Gap Analysis — =IFERROR((TotalAchievedWeight/TotalPossibleWeight)*100,0)
A26: JobDescriptionText | B26: Skills Gap Analysis!$A$4 — Paste job posting text here
A28: KPI FORMULAS
A29: Applications This Week: | B29: =COUNTIFS(Log!A:A,">="&TODAY()-7) -> 0
A30: Follow-Ups Due: | B30: =COUNTIFS(Log!H:H,"<"&TODAY(),Log!G:G,"Applied") -> 2
A31: Interview Rate: | B31: =IFERROR(COUNTIF(Log!G:G,"Interview Scheduled")/(COUNTA(Log!A:A)-1),0) -> 0.16666667
A32: Offer Rate: | B32: =IFERROR(COUNTIF(Log!G:G,"Offer")/(COUNTA(Log!A:A)-1),0) -> 0
A34: HEALTH SCORE FORMULAS
A35: ScoreA (0–30): | B35: =MIN((COUNTIFS(Log!A:A,">="&TODAY()-7)/5)*30,30) -> 0
A36: ScoreB (0–30): | B36: =MAX(30-(COUNTIFS(Log!H:H,"<"&TODAY(),Log!G:G,"Applied")*10),0) -> 10
A37: ScoreC (0–25): | B37: =IFERROR(MIN((COUNTIF(Log!G:G,"Interview Scheduled")/(COUNTA(Log!A:A)-1))*25,25),0) -> 4.1666667
A38: ScoreD (0–15): | B38: =IFERROR(MIN((COUNTIF(Log!G:G,"Offer")/(COUNTA(Log!A:A)-1))*15,15),0) -> 0
A39: Final Score: | B39: =ScoreA+ScoreB+ScoreC+ScoreD -> 14.166667
A41: SKILLS GAP FORMULAS
A42: Is In Resume: | B42: =IF(COUNTIF(ResumeSkills[Skill],[@Skill])>0,1,0)
A43: Weighted Score: | B43: =[@Weight]*[@[Is In Resume]]
A44: Weighted Gap: | B44: =IF([@[Is In Resume]]=1,0,[@Weight])
A45: Gap Rank: | B45: =RANK([@[Weighted Gap]],SkillsGap[Weighted Gap],0)
...
